<?xml version="1.0" ?>
<!-- =================================================================================== -->
<!-- |    This document was autogenerated by xacro from sphero_rvr.urdf.xacro          | -->
<!-- |    EDITING THIS FILE BY HAND IS NOT RECOMMENDED                                 | -->
<!-- =================================================================================== -->
<robot name="track_robot">
  <!-- material block colours -->
  <material name="Blue">
    <color rgba="0.0 0.0 0.8 1.0"/>
  </material>
  <material name="Green">
    <color rgba="0.0 0.8 0.0 1.0"/>
  </material>
  <material name="Red">
    <color rgba="0.8 0.0 0.0 1.0"/>
  </material>
  <material name="White">
    <color rgba="1.0 1.0 1.0 1.0"/>
  </material>
  <material name="Black">
    <color rgba="0.1 0.1 0.1 1.0"/>
  </material>
  <material name="DarkGrey">
    <color rgba="0.4 0.4 0.4 1.0"/>
  </material>
  <material name="DarkGrey2">
    <color rgba="0.3 0.3 0.3 1.0"/>
  </material>
  <material name="LightGrey">
    <color rgba="0.6 0.6 0.6 1.0"/>
  </material>
  <material name="LightGrey2">
    <color rgba="0.9 0.9 0.9 1.0"/>
  </material>
  <material name="Brown">
    <color rgba="0.8 0.7 0.5 1.0"/>
  </material>
  <material name="dark_grey">
    <color rgba="0.2 0.2 0.2 1.0"/>
  </material>
  <!-- dummy base link no inertia to satisfy kdl -->
  <link name="base_link"/>
  <!-- Base footprint is on the ground under the robot -->
  <link name="base_footprint"/>
  <joint name="base_footprint_joint" type="fixed">
    <origin rpy="0 0 0" xyz="0 0 -0.025"/>
    <parent link="base_link"/>
    <child link="base_footprint"/>
  </joint>
  <!-- attach body to base_link -->
  <joint name="body_inertia" type="fixed">
    <parent link="base_link"/>
    <child link="body"/>
  </joint>
  <link name="body">
    <visual>
      <geometry>
        <mesh filename="package://greeter_description/meshes/body.dae"/>
      </geometry>
      <material name="White"/>
    </visual>
    <collision>
      <geometry>
        <box size="0.182 0.138 0.043"/>
      </geometry>
    </collision>
    <inertial>
      <origin rpy="0 0 0" xyz="0 0 0"/>
      <mass value="2.00"/>
      <inertia ixx="0.005" ixy="0.0" ixz="0.0" iyy="0.005" iyz="0.0" izz="0.005"/>
    </inertial>
  </link>
  <gazebo reference="body">
    <mu1 value="1.0"/>
    <mu2 value="1.0"/>
    <kp value="10000000.0"/>
    <kd value="1.0"/>
    <fdir1 value="1 0 0"/>
  </gazebo>
  <joint name="left_track_back_wheel_joint" type="continuous">
    <parent link="base_link"/>
    <child link="left_track_back_wheel"/>
    <origin rpy="0 0 0" xyz="-0.062 0.069 0.0075"/>
    <axis rpy="0 0 0" xyz="0 1 0"/>
    <limit effort="10.0" velocity="50.0"/>
  </joint>
  <link name="left_track_back_wheel">
    <visual>
      <origin rpy="1.5707963267948966 0 0" xyz="0 0.0175 0"/>
      <geometry>
        <cylinder length="0.035" radius="0.0325"/>
      </geometry>
      <material name="DarkGrey"/>
    </visual>
    <collision>
      <origin rpy="1.5707963267948966 0 0" xyz="0 0.0175 0"/>
      <geometry>
        <cylinder length="0.036750000000000005" radius="0.034125"/>
      </geometry>
    </collision>
    <inertial>
      <origin rpy="0 0 0" xyz="0 0 0"/>
      <mass value="0.076"/>
      <inertia ixx="0.001" ixy="0.0" ixz="0.0" iyy="0.001" iyz="0.0" izz="0.001"/>
    </inertial>
  </link>
  <joint name="left_track_back_wheel_taco_joint" type="fixed">
    <parent link="left_track_back_wheel"/>
    <child link="left_track_back_wheel_taco"/>
    <origin rpy="0 0 0" xyz="0 0.0175 0.034125"/>
  </joint>
  <link name="left_track_back_wheel_taco">
    <visual>
      <geometry>
        <cylinder length="0.004" radius="0.005"/>
      </geometry>
      <material name="Red"/>
    </visual>
  </link>
  <gazebo reference="left_track_back_wheel">
    <mu1 value="0.8"/>
    <mu2 value="0.8"/>
    <kp value="10000000.0"/>
    <kd value="1.0"/>
    <fdir1 value="1 0 0"/>
  </gazebo>
  <transmission name="left_track_back_wheel_trans" type="SimpleTransmission">
    <type>transmission_interface/SimpleTransmission</type>
    <actuator name="left_track_back_wheel_motor">
      <mechanicalReduction>1</mechanicalReduction>
    </actuator>
    <joint name="left_track_back_wheel_joint">
      <hardwareInterface>hardware_interface/VelocityJointInterface</hardwareInterface>
    </joint>
  </transmission>
  <joint name="left_track_front_wheel_joint" type="continuous">
    <parent link="base_link"/>
    <child link="left_track_front_wheel"/>
    <origin rpy="0 0 0" xyz="0.062 0.069 0.0075"/>
    <axis rpy="0 0 0" xyz="0 1 0"/>
    <limit effort="10.0" velocity="50.0"/>
  </joint>
  <link name="left_track_front_wheel">
    <visual>
      <origin rpy="1.5707963267948966 0 0" xyz="0 0.0175 0"/>
      <geometry>
        <cylinder length="0.035" radius="0.0325"/>
      </geometry>
      <material name="DarkGrey"/>
    </visual>
    <collision>
      <origin rpy="1.5707963267948966 0 0" xyz="0 0.0175 0"/>
      <geometry>
        <cylinder length="0.036750000000000005" radius="0.034125"/>
      </geometry>
    </collision>
    <inertial>
      <origin rpy="0 0 0" xyz="0 0 0"/>
      <mass value="0.076"/>
      <inertia ixx="0.001" ixy="0.0" ixz="0.0" iyy="0.001" iyz="0.0" izz="0.001"/>
    </inertial>
  </link>
  <joint name="left_track_front_wheel_taco_joint" type="fixed">
    <parent link="left_track_front_wheel"/>
    <child link="left_track_front_wheel_taco"/>
    <origin rpy="0 0 0" xyz="0 0.0175 0.034125"/>
  </joint>
  <link name="left_track_front_wheel_taco">
    <visual>
      <geometry>
        <cylinder length="0.004" radius="0.005"/>
      </geometry>
      <material name="Red"/>
    </visual>
  </link>
  <gazebo reference="left_track_front_wheel">
    <mu1 value="0.8"/>
    <mu2 value="0.8"/>
    <kp value="10000000.0"/>
    <kd value="1.0"/>
    <fdir1 value="1 0 0"/>
  </gazebo>
  <transmission name="left_track_front_wheel_trans" type="SimpleTransmission">
    <type>transmission_interface/SimpleTransmission</type>
    <actuator name="left_track_front_wheel_motor">
      <mechanicalReduction>1</mechanicalReduction>
    </actuator>
    <joint name="left_track_front_wheel_joint">
      <hardwareInterface>hardware_interface/VelocityJointInterface</hardwareInterface>
    </joint>
  </transmission>
  <joint name="right_track_back_wheel_joint" type="continuous">
    <parent link="base_link"/>
    <child link="right_track_back_wheel"/>
    <origin rpy="3.141592653589793 0 0" xyz="-0.062 -0.069 0.0075"/>
    <axis rpy="0 0 0" xyz="0 -1 0"/>
    <limit effort="10.0" velocity="50.0"/>
  </joint>
  <link name="right_track_back_wheel">
    <visual>
      <origin rpy="1.5707963267948966 0 0" xyz="0 0.0175 0"/>
      <geometry>
        <cylinder length="0.035" radius="0.0325"/>
      </geometry>
      <material name="DarkGrey"/>
    </visual>
    <collision>
      <origin rpy="1.5707963267948966 0 0" xyz="0 0.0175 0"/>
      <geometry>
        <cylinder length="0.036750000000000005" radius="0.034125"/>
      </geometry>
    </collision>
    <inertial>
      <origin rpy="0 0 0" xyz="0 0 0"/>
      <mass value="0.076"/>
      <inertia ixx="0.001" ixy="0.0" ixz="0.0" iyy="0.001" iyz="0.0" izz="0.001"/>
    </inertial>
  </link>
  <joint name="right_track_back_wheel_taco_joint" type="fixed">
    <parent link="right_track_back_wheel"/>
    <child link="right_track_back_wheel_taco"/>
    <origin rpy="0 0 0" xyz="0 0.0175 0.034125"/>
  </joint>
  <link name="right_track_back_wheel_taco">
    <visual>
      <geometry>
        <cylinder length="0.004" radius="0.005"/>
      </geometry>
      <material name="Red"/>
    </visual>
  </link>
  <gazebo reference="right_track_back_wheel">
    <mu1 value="0.8"/>
    <mu2 value="0.8"/>
    <kp value="10000000.0"/>
    <kd value="1.0"/>
    <fdir1 value="1 0 0"/>
  </gazebo>
  <transmission name="right_track_back_wheel_trans" type="SimpleTransmission">
    <type>transmission_interface/SimpleTransmission</type>
    <actuator name="right_track_back_wheel_motor">
      <mechanicalReduction>1</mechanicalReduction>
    </actuator>
    <joint name="right_track_back_wheel_joint">
      <hardwareInterface>hardware_interface/VelocityJointInterface</hardwareInterface>
    </joint>
  </transmission>
  <joint name="right_track_front_wheel_joint" type="continuous">
    <parent link="base_link"/>
    <child link="right_track_front_wheel"/>
    <origin rpy="3.141592653589793 0 0" xyz="0.062 -0.069 0.0075"/>
    <axis rpy="0 0 0" xyz="0 -1 0"/>
    <limit effort="10.0" velocity="50.0"/>
  </joint>
  <link name="right_track_front_wheel">
    <visual>
      <origin rpy="1.5707963267948966 0 0" xyz="0 0.0175 0"/>
      <geometry>
        <cylinder length="0.035" radius="0.0325"/>
      </geometry>
      <material name="DarkGrey"/>
    </visual>
    <collision>
      <origin rpy="1.5707963267948966 0 0" xyz="0 0.0175 0"/>
      <geometry>
        <cylinder length="0.036750000000000005" radius="0.034125"/>
      </geometry>
    </collision>
    <inertial>
      <origin rpy="0 0 0" xyz="0 0 0"/>
      <mass value="0.076"/>
      <inertia ixx="0.001" ixy="0.0" ixz="0.0" iyy="0.001" iyz="0.0" izz="0.001"/>
    </inertial>
  </link>
  <joint name="right_track_front_wheel_taco_joint" type="fixed">
    <parent link="right_track_front_wheel"/>
    <child link="right_track_front_wheel_taco"/>
    <origin rpy="0 0 0" xyz="0 0.0175 0.034125"/>
  </joint>
  <link name="right_track_front_wheel_taco">
    <visual>
      <geometry>
        <cylinder length="0.004" radius="0.005"/>
      </geometry>
      <material name="Red"/>
    </visual>
  </link>
  <gazebo reference="right_track_front_wheel">
    <mu1 value="0.8"/>
    <mu2 value="0.8"/>
    <kp value="10000000.0"/>
    <kd value="1.0"/>
    <fdir1 value="1 0 0"/>
  </gazebo>
  <transmission name="right_track_front_wheel_trans" type="SimpleTransmission">
    <type>transmission_interface/SimpleTransmission</type>
    <actuator name="right_track_front_wheel_motor">
      <mechanicalReduction>1</mechanicalReduction>
    </actuator>
    <joint name="right_track_front_wheel_joint">
      <hardwareInterface>hardware_interface/VelocityJointInterface</hardwareInterface>
    </joint>
  </transmission>
  <!-- gazebo extras -->
  <!-- gazebo control -->
  <gazebo>
    <plugin filename="libgazebo_ros_control.so" name="gazebo_ros_control">
      <robotNamespace>/</robotNamespace>
    </plugin>
  </gazebo>
  <!-- imu -->
  <gazebo>
    <plugin filename="libhector_gazebo_ros_imu.so" name="imu_controller">
      <robotNamespace>/</robotNamespace>
      <alwaysOn>true</alwaysOn>
      <updateRate>10.0</updateRate>
      <bodyName>base_link</bodyName>
      <topicName>rvr_driver/imu/data</topicName>
      <accelDrift>0.001 0.001 0.001</accelDrift>
      <accelGaussianNoise>0.001 0.001 0.001</accelGaussianNoise>
      <rateDrift>0.001 0.001 0.001</rateDrift>
      <rateGaussianNoise>0.005 0.005 0.005 </rateGaussianNoise>
      <headingDrift>0.001</headingDrift>
      <headingGaussianNoise>0.005</headingGaussianNoise>
      <xyzOffsets>0 0 0</xyzOffsets>
      <rpyOffsets>0 0 0</rpyOffsets>
    </plugin>
  </gazebo>
</robot>
